<mujoco model="steval_pendel">
  <compiler angle="radian"/>

  <asset>
    <mesh name="base" content_type="model/stl" file="assets/base.stl"/>
    <mesh name="rotary" content_type="model/stl" file="assets/rotary.stl"/>
    <mesh name="pendel" content_type="model/stl" file="assets/pendel.stl"/>
  </asset>
  
  <default>
    <default class="damped_joint">
        <joint damping="0.1"/>
    </default>
    <joint damping="0.001"/>
  </default>

  <worldbody>
    <geom type="mesh" rgba="0.231373 0.380392 0.705882 1" mesh="base"/>
    
    <body name="rotary" pos="0 0 0.32" quat="1.32679e-06 -1 0 0">
      <inertial pos="-3.60568e-09 0 -0.0199935" quat="0.707106 -0.000328919 -0.000328918 0.707108" mass="0.101821" diaginertia="2.03712e-05 1.78261e-05 1.78134e-05"/>
      
      <joint name="rotary" class="damped_joint" pos="0 0 0" axis="0 0 1" range="-4.71239 4.71239"/> 
      
      <geom pos="0 0 0.32" quat="1.32679e-06 1 0 0" type="mesh" rgba="0.372549 0.654902 0.239216 1" mesh="rotary"/>
      
      <body name="pendel" pos="0 -0.015 -0.02" quat="0.707105 -0.707108 0 0">
        <inertial pos="0 -0.0771612 -0.10421" quat="0.543661 0.839305 0 0" mass="0.0362517" diaginertia="0.000359053 0.000313828 4.56366e-05"/>
        <joint name="pendel" pos="0 0 0" axis="0 0 1"/>
        <geom pos="0 -0.34 0.015" quat="0.707105 -0.707108 0 0" type="mesh" rgba="1 0 0 1" mesh="pendel"/>
      </body>
    </body>
  </worldbody>
  
  <actuator>
    <velocity name="rotary_velocity_control" joint="rotary" gear="10"/>
  </actuator>
  
</mujoco>