<?xml version="1.0" ?>
<!-- Generated using onshape-to-robot -->
<!-- Onshape document_id: e42e43c310dfcd9f2ea84215 -->
<robot name="steval_pendel">
  <!-- Link base -->
  <link name="base">
    <inertial>
      <origin xyz="-1.11462e-18 -9.98673e-38 0.155083" rpy="0 0 0"/>
      <mass value="4.10342"/>
      <inertia ixx="0.0345736" ixy="0" ixz="0" iyy="0.0345736" iyz="0" izz="0.00334942"/>
    </inertial>
    <!-- Part base -->
    <visual>
      <origin xyz="0 0 0" rpy="0 -0 0"/>
      <geometry>
        <mesh filename="assets/base.stl"/>
      </geometry>
      <material name="base_material">
        <color rgba="0.231373 0.380392 0.705882 1"/>
      </material>
    </visual>
    <collision>
      <origin xyz="0 0 0" rpy="0 -0 0"/>
      <geometry>
        <mesh filename="assets/base.stl"/>
      </geometry>
    </collision>
  </link>
  <!-- Link rotary -->
  <link name="rotary">
    <inertial>
      <origin xyz="-3.60568e-09 -2.17845e-18 -0.0199935" rpy="0 0 0"/>
      <mass value="0.101821"/>
      <inertia ixx="1.78261e-05" ixy="-6.06383e-12" ixz="1.18151e-11" iyy="2.03712e-05" iyz="1.7677e-76" izz="1.78134e-05"/>
    </inertial>
    <!-- Part rotary -->
    <visual>
      <origin xyz="1.71057e-49 0 0.32" rpy="3.14159 -0 1.49614e-65"/>
      <geometry>
        <mesh filename="assets/rotary.stl"/>
      </geometry>
      <material name="rotary_material">
        <color rgba="0.372549 0.654902 0.239216 1"/>
      </material>
    </visual>
    <collision>
      <origin xyz="1.71057e-49 0 0.32" rpy="3.14159 -0 1.49614e-65"/>
      <geometry>
        <mesh filename="assets/rotary.stl"/>
      </geometry>
    </collision>
  </link>
  <!-- Link pendel -->
  <link name="pendel">
    <inertial>
      <origin xyz="1.63456e-20 -0.0771612 -0.10421" rpy="0 0 0"/>
      <mass value="0.0362517"/>
      <inertia ixx="0.000359053" ixy="0" ixz="1.45364e-48" iyy="9.04706e-05" iyz="-0.00010007" izz="0.000268994"/>
    </inertial>
    <!-- Part pendel -->
    <visual>
      <origin xyz="-1.97215e-31 -0.34 0.015" rpy="-1.5708 -4.04854e-45 0"/>
      <geometry>
        <mesh filename="assets/pendel.stl"/>
      </geometry>
      <material name="pendel_material">
        <color rgba="1 0 0 1"/>
      </material>
    </visual>
    <collision>
      <origin xyz="-1.97215e-31 -0.34 0.015" rpy="-1.5708 -4.04854e-45 0"/>
      <geometry>
        <mesh filename="assets/pendel.stl"/>
      </geometry>
    </collision>
  </link>
  <!-- Joint from rotary to pendel -->
<joint name="pendel" type="continuous">
  <origin xyz="-1.73445e-32 -0.015 -0.02" rpy="-1.5708 2.85232e-15 -1.92285e-30"/>
  <parent link="rotary"/>
  <child link="pendel"/>
  <axis xyz="0 0 1"/>
  </joint>
  
  <!-- Joint from base to rotary -->
  <joint name="rotary" type="revolute">
    <origin xyz="-3.26654e-34 -4.34338e-33 0.32" rpy="-3.14159 3.79403e-33 -5.55112e-17"/>
    <parent link="base"/>
    <child link="rotary"/>
    <axis xyz="0 0 1"/>
    <limit effort="10" velocity="10" lower="-4.71239" upper="4.71239"/>
  </joint>
</robot>
