<mujoco model="steval_pendel_revised">
  <option iterations="50" timestep="0.001" solver="PGS" gravity="0 0 -9.81" />

  <compiler angle="radian" meshdir="assets" eulerseq="zyx" autolimits="true" />

  <default>
    <joint limited="true" damping="0.01" armature="0.01" frictionloss="0.01" />
    <geom condim="4" contype="1" conaffinity="15" friction="0.9 0.2 0.2" solref="0.001 2" />
    <motor ctrllimited="true" />
    <equality solref="0.001 2" />
    <default class="visualgeom">
      <geom material="visualgeom" condim="1" contype="0" conaffinity="0" />
    </default>
  </default>

  <asset>
    <mesh name="base" content_type="model/stl" file="base.stl" />
    <mesh name="rotary" content_type="model/stl" file="rotary.stl" />
    <mesh name="pendel" content_type="model/stl" file="pendel.stl" />
    <texture name="texplane" type="2d" builtin="checker" rgb1=".0 .0 .0" rgb2=".8 .8 .8" width="100" height="100" />
    <material name="matplane" reflectance="0." texture="texplane" texrepeat="1 1" texuniform="true" />
    <material name="visualgeom" rgba="0.5 0.9 0.2 1" />
  </asset>

  <worldbody>
    <light directional="true" diffuse="0.4 0.4 0.4" specular="0.1 0.1 0.1" pos="0 0 5.0" dir="0 0 -1" castshadow="false" />
    <light directional="true" diffuse="0.6 0.6 0.6" specular="0.2 0.2 0.2" pos="0 0 4" dir="0 0 -1" />
    <geom name="ground" type="plane" pos="0 0 0" size="100 100 0.001" quat="1 0 0 0" material="matplane" condim="3" conaffinity="15" />
    <camera name="fixed" pos="0 -3.0 0.5098348300018851" xyaxes="1 0 0 0 0 1" />
    <camera name="track" mode="trackcom" pos="0 -3.0 0.5098348300018851" xyaxes="1 0 0 0 0 1" />
    
    <body name="base" pos="0 0 0.009834830001885175" quat="1 0 0 0">
      <site name="imu" size="0.01" pos="0 0 0" />
      <geom type="mesh" rgba="0.231373 0.380392 0.705882 1" mesh="base" contype="1" conaffinity="0" density="0" group="1" class="visualgeom" />
      <geom type="mesh" rgba="0.231373 0.380392 0.705882 1" mesh="base" />
      
      <body name="rotary" pos="0 0 0.32" quat="1.32679e-06 -1 0 0">
        <inertial pos="-3.60568e-09 0 -0.0199935" quat="0.707106 -0.000328919 -0.000328918 0.707108" mass="0.101821" diaginertia="2.03712e-05 1.78261e-05 1.78134e-05" />
        <joint name="rotary" pos="0 0 0" axis="0 0 1" range="-4.71239 4.71239" actuatorfrcrange="-10 10" />
        <geom pos="0 0 0.32" quat="1.32679e-06 1 0 0" type="mesh" rgba="0.372549 0.654902 0.239216 1" mesh="rotary" contype="1" conaffinity="0" density="0" group="1" class="visualgeom" />
        <geom type="mesh" rgba="0.372549 0.654902 0.239216 1" mesh="rotary" pos="0 0 0.32" quat="1.32679e-06 1 0 0" />
        
        <body name="pendel" pos="0 -0.015 -0.02" quat="0.707105 -0.707108 0 0">
          <inertial pos="0 -0.0771612 -0.10421" quat="0.543661 0.839305 0 0" mass="0.0362517" diaginertia="0.000359053 0.000313828 4.56366e-05" />
          <joint name="pendel" pos="0 0 0" axis="0 0 1" limited="false" />
          <geom pos="0 -0.34 0.015" quat="0.707105 -0.707108 0 0" type="mesh" rgba="1 0 0 1" mesh="pendel" contype="1" conaffinity="0" density="0" group="1" class="visualgeom" />
          <geom type="mesh" rgba="1 0 0 1" mesh="pendel" pos="0 -0.34 0.015" quat="0.707105 -0.707108 0 0" />
        </body >
      </body >
    </body >
  </worldbody>

  <actuator>
    <velocity name="rotary" joint="rotary" ctrllimited="true" ctrlrange="-10 10" gear="1" forcelimited="true" forcerange="-10 10" />
  </actuator>

  <sensor>
    <actuatorpos name="rotary_p" actuator="rotary" />
    <actuatorvel name="rotary_v" actuator="rotary" />
    <actuatorfrc name="rotary_f" actuator="rotary" noise="0.001" />
    <jointpos name="pendel_p" joint="pendel" />
    <jointvel name="pendel_v" joint="pendel" />
    <framequat name="orientation" objtype="site" noise="0.001" objname="imu" />
    <gyro name="angular-velocity" site="imu" noise="0.005" cutoff="34.9" />
  </sensor>
</mujoco>